Workbook

Sheet datos_limpios
A1: id_producto | B1: categoria | C1: grupo | D1: producto | E1: precio_lista | F1: descuento_pct | G1: precio_venta | H1: ahorro_unitario | I1: cantidad_disponible | J1: agotado | K1: agotado_num | L1: nivel_stock | M1: valor_inventario | N1: ahorro_potencial | O1: peso_gramos | P1: cantidad_paquete | Q1: rango_precio | R1: rango_descuento | S1: n_categorias | T1: es_listado_principal
A2: P0001 | B2: Fruits & Vegetables | C2: Alimentos y bebidas | D2: Onion | E2: 25 | F2: 16 | G2: 21 | H2: =ROUND(E2-G2,2) -> 4 | I2: 3 | J2: =FALSE() -> FALSE | K2: =IF(J2,1,0) -> 0 | L2: Medio (3-5) | M2: =ROUND(G2*I2,2) -> 63 | N2: =ROUND(H2*I2,2) -> 12 | O2: 1000 | P2: 1 | Q2: 0-50 | R2: 11-20% | S2: 1 | T2: 1
A3: P0002 | B3: Fruits & Vegetables | C3: Alimentos y bebidas | D3: Tomato Hybrid | E3: 42 | F3: 16 | G3: 35 | H3: =ROUND(E3-G3,2) -> 7 | I3: 3 | J3: =FALSE() -> FALSE | K3: =IF(J3,1,0) -> 0 | L3: Medio (3-5) | M3: =ROUND(G3*I3,2) -> 105 | N3: =ROUND(H3*I3,2) -> 21 | O3: 1000 | P3: 1 | Q3: 0-50 | R3: 11-20% | S3: 1 | T3: 1
A4: P0003 | B4: Fruits & Vegetables | C4: Alimentos y bebidas | D4: Tender Coconut | E4: 51 | F4: 15 | G4: 43 | H4: =ROUND(E4-G4,2) -> 8 | I4: 3 | J4: =FALSE() -> FALSE | K4: =IF(J4,1,0) -> 0 | L4: Medio (3-5) | M4: =ROUND(G4*I4,2) -> 129 | N4: =ROUND(H4*I4,2) -> 24 | O4: 58 | P4: 1 | Q4: 51-100 | R4: 11-20% | S4: 1 | T4: 1
A5: P0004 | B5: Fruits & Vegetables | C5: Alimentos y bebidas | D5: Coriander Leaves | E5: 20 | F5: 15 | G5: 17 | H5: =ROUND(E5-G5,2) -> 3 | I5: 3 | J5: =FALSE() -> FALSE | K5: =IF(J5,1,0) -> 0 | L5: Medio (3-5) | M5: =ROUND(G5*I5,2) -> 51 | N5: =ROUND(H5*I5,2) -> 9 | O5: 100 | P5: 100 | Q5: 0-50 | R5: 11-20% | S5: 1 | T5: 1
A6: P0005 | B6: Fruits & Vegetables | C6: Alimentos y bebidas | D6: Ladies Finger | E6: 14 | F6: 14 | G6: 12 | H6: =ROUND(E6-G6,2) -> 2 | I6: 3 | J6: =FALSE() -> FALSE | K6: =IF(J6,1,0) -> 0 | L6: Medio (3-5) | M6: =ROUND(G6*I6,2) -> 36 | N6: =ROUND(H6*I6,2) -> 6 | O6: 250 | P6: 250 | Q6: 0-50 | R6: 11-20% | S6: 1 | T6: 1
A7: P0006 | B7: Fruits & Vegetables | C7: Alimentos y bebidas | D7: Potato | E7: 35 | F7: 17 | G7: 29 | H7: =ROUND(E7-G7,2) -> 6 | I7: 3 | J7: =FALSE() -> FALSE | K7: =IF(J7,1,0) -> 0 | L7: Medio (3-5) | M7: =ROUND(G7*I7,2) -> 87 | N7: =ROUND(H7*I7,2) -> 18 | O7: 1000 | P7: 1 | Q7: 0-50 | R7: 11-20% | S7: 1 | T7: 1
A8: P0007 | B8: Fruits & Vegetables | C8: Alimentos y bebidas | D8: Lemon | E8: 75 | F8: 16 | G8: 63 | H8: =ROUND(E8-G8,2) -> 12 | I8: 3 | J8: =FALSE() -> FALSE | K8: =IF(J8,1,0) -> 0 | L8: Medio (3-5) | M8: =ROUND(G8*I8,2) -> 189 | N8: =ROUND(H8*I8,2) -> 36 | O8: 200 | P8: 200 | Q8: 51-100 | R8: 11-20% | S8: 1 | T8: 1
A9: P0008 | B9: Fruits & Vegetables | C9: Alimentos y bebidas | D9: Watermelon | E9: 58 | F9: 15 | G9: 49 | H9: =ROUND(E9-G9,2) -> 9 | I9: 3 | J9: =FALSE() -> FALSE | K9: =IF(J9,1,0) -> 0 | L9: Medio (3-5) | M9: =ROUND(G9*I9,2) -> 147 | N9: =ROUND(H9*I9,2) -> 27 | O9: 58 | P9: 1 | Q9: 51-100 | R9: 11-20% | S9: 1 | T9: 1
A10: P0009 | B10: Fruits & Vegetables | C10: Alimentos y bebidas | D10: Capsicum Green | E10: 23 | F10: 17 | G10: 19 | H10: =ROUND(E10-G10,2) -> 4 | I10: 3 | J10: =FALSE() -> FALSE | K10: =IF(J10,1,0) -> 0 | L10: Medio (3-5) | M10: =ROUND(G10*I10,2) -> 57 | N10: =ROUND(H10*I10,2) -> 12 | O10: 250 | P10: 250 | Q10: 0-50 | R10: 11-20% | S10: 1 | T10: 1
A11: P0010 | B11: Fruits & Vegetables | C11: Alimentos y bebidas | D11: Chilli Green | E11: 19 | F11: 15 | G11: 16 | H11: =ROUND(E11-G11,2) -> 3 | I11: 3 | J11: =FALSE() -> FALSE | K11: =IF(J11,1,0) -> 0 | L11: Medio (3-5) | M11: =ROUND(G11*I11,2) -> 48 | N11: =ROUND(H11*I11,2) -> 9 | O11: 100 | P11: 100 | Q11: 0-50 | R11: 11-20% | S11: 1 | T11: 1
A12: P0011 | B12: Fruits & Vegetables | C12: Alimentos y bebidas | D12: Banana Robusta | E12: 29 | F12: 17 | G12: 24 | H12: =ROUND(E12-G12,2) -> 5 | I12: 3 | J12: =FALSE() -> FALSE | K12: =IF(J12,1,0) -> 0 | L12: Medio (3-5) | M12: =ROUND(G12*I12,2) -> 72 | N12: =ROUND(H12*I12,2) -> 15 | O12: 348 | P12: 6 | Q12: 0-50 | R12: 11-20% | S12: 1 | T12: 1
A13: P0012 | B13: Fruits & Vegetables | C13: Alimentos y bebidas | D13: Garlic Indian | E13: 11 | F13: 18 | G13: 9 | H13: =ROUND(E13-G13,2) -> 2 | I13: 3 | J13: =FALSE() -> FALSE | K13: =IF(J13,1,0) -> 0 | L13: Medio (3-5) | M13: =ROUND(G13*I13,2) -> 27 | N13: =ROUND(H13*I13,2) -> 6 | O13: 100 | P13: 100 | Q13: 0-50 | R13: 11-20% | S13: 1 | T13: 1
... A88: P0087 | B88: Fruits & Vegetables | C88: Alimentos y bebidas | D88: Garlic | E88: 17 | F88: 23 | G88: 13 | H88: =ROUND(E88-G88,2) -> 4 | I88: 3 | J88: =FALSE() -> FALSE | K88: =IF(J88,1,0) -> 0 | L88: Medio (3-5) | M88: =ROUND(G88*I88,2) -> 39 | N88: =ROUND(H88*I88,2) -> 12 | O88: 200 | P88: 200 | Q88: 0-50 | R88: 21% o mas | S88: 1 | T88: 1
A89: P0088 | B89: Fruits & Vegetables | C89: Alimentos y bebidas | D89: Carrot | E89: 13 | F89: 15 | G89: 11 | H89: =ROUND(E89-G89,2) -> 2 | I89: 0 | J89: =TRUE() -> TRUE | K89: =IF(J89,1,0) -> 1 | L89: Agotado | M89: =ROUND(G89*I89,2) -> 0 | N89: =ROUND(H89*I89,2) -> 0 | O89: 250 | P89: 200 | Q89: 0-50 | R89: 11-20% | S89: 1 | T89: 1
A90: P0089 | B90: Fruits & Vegetables | C90: Alimentos y bebidas | D90: Beetroot | E90: 11 | F90: 18 | G90: 9 | H90: =ROUND(E90-G90,2) -> 2 | I90: 0 | J90: =TRUE() -> TRUE | K90: =IF(J90,1,0) -> 1 | L90: Agotado | M90: =ROUND(G90*I90,2) -> 0 | N90: =ROUND(H90*I90,2) -> 0 | O90: 250 | P90: 250 | Q90: 0-50 | R90: 11-20% | S90: 1 | T90: 1
A91: P0090 | B91: Fruits & Vegetables | C91: Alimentos y bebidas | D91: Moong Sprouts | E91: 35 | F91: 17 | G91: 29 | H91: =ROUND(E91-G91,2) -> 6 | I91: 0 | J91: =TRUE() -> TRUE | K91: =IF(J91,1,0) -> 1 | L91: Agotado | M91: =ROUND(G91*I91,2) -> 0 | N91: =ROUND(H91*I91,2) -> 0 | O91: 200 | P91: 200 | Q91: 0-50 | R91: 11-20% | S91: 1 | T91: 1
A92: P0091 | B92: Fruits & Vegetables | C92: Alimentos y bebidas | D92: Safal Frozen Mixed Vegetables | E92: 60 | F92: 5 | G92: 57 | H92: =ROUND(E92-G92,2) -> 3 | I92: 0 | J92: =TRUE() -> TRUE | K92: =IF(J92,1,0) -> 1 | L92: Agotado | M92: =ROUND(G92*I92,2) -> 0 | N92: =ROUND(H92*I92,2) -> 0 | O92: 500 | P92: 500 | Q92: 51-100 | R92: 1-10% | S92: 4 | T92: 1
A93: P0092 | B93: Fruits & Vegetables | C93: Alimentos y bebidas | D93: Safal Frozen Corn | E93: 41 | F93: 4 | G93: 39 | H93: =ROUND(E93-G93,2) -> 2 | I93: 0 | J93: =TRUE() -> TRUE | K93: =IF(J93,1,0) -> 1 | L93: Agotado | M93: =ROUND(G93*I93,2) -> 0 | N93: =ROUND(H93*I93,2) -> 0 | O93: 200 | P93: 200 | Q93: 0-50 | R93: 1-10% | S93: 4 | T93: 1
A94: P0093 | B94: Fruits & Vegetables | C94: Alimentos y bebidas | D94: Safal Frozen - Sweet Corn | E94: 160 | F94: 5 | G94: 152 | H94: =ROUND(E94-G94,2) -> 8 | I94: 0 | J94: =TRUE() -> TRUE | K94: =IF(J94,1,0) -> 1 | L94: Agotado | M94: =ROUND(G94*I94,2) -> 0 | N94: =ROUND(H94*I94,2) -> 0 | O94: 1000 | P94: 1 | Q94: 101-200 | R94: 1-10% | S94: 4 | T94: 1
A95: P0094 | B95: Cooking Essentials | C95: Alimentos y bebidas | D95: Maggi 2 Minute Masala Noodles | E95: 12 | F95: 0 | G95: 12 | H95: =ROUND(E95-G95,2) -> 0 | I95: 6 | J95: =FALSE() -> FALSE | K95: =IF(J95,1,0) -> 0 | L95: Alto (6) | M95: =ROUND(G95*I95,2) -> 72 | N95: =ROUND(H95*I95,2) -> 0 | O95: 70 | P95: 70 | Q95: 0-50 | R95: Sin descuento | S95: 5 | T95: 1
A96: P0095 | B96: Cooking Essentials | C96: Alimentos y bebidas | D96: iD Idli & Dosa Batter | E96: 80 | F96: 15 | G96: 68 | H96: =ROUND(E96-G96,2) -> 12 | I96: 6 | J96: =FALSE() -> FALSE | K96: =IF(J96,1,0) -> 0 | L96: Alto (6) | M96: =ROUND(G96*I96,2) -> 408 | N96: =ROUND(H96*I96,2) -> 72 | O96: 1000 | P96: 1 | Q96: 51-100 | R96: 11-20% | S96: 7 | T96: 1
A97: P0096 | B97: Cooking Essentials | C97: Alimentos y bebidas | D97: Tata Salt | E97: 24 | F97: 0 | G97: 24 | H97: =ROUND(E97-G97,2) -> 0 | I97: 6 | J97: =FALSE() -> FALSE | K97: =IF(J97,1,0) -> 0 | L97: Alto (6) | M97: =ROUND(G97*I97,2) -> 144 | N97: =ROUND(H97*I97,2) -> 0 | O97: 1000 | P97: 1 | Q97: 0-50 | R97: Sin descuento | S97: 2 | T97: 1
A98: P0097 | B98: Cooking Essentials | C98: Alimentos y bebidas | D98: Arden Eggs White | E98: 97 | F98: 0 | G98: 97 | H98: =ROUND(E98-G98,2) -> 0 | I98: 4 | J98: =FALSE() -> FALSE | K98: =IF(J98,1,0) -> 0 | L98: Medio (3-5) | M98: =ROUND(G98*I98,2) -> 388 | N98: =ROUND(H98*I98,2) -> 0 | O98: 696 | P98: 12 | Q98: 51-100 | R98: Sin descuento | S98: 5 | T98: 1
A99: P0098 | B99: Cooking Essentials | C99: Alimentos y bebidas | D99: Arden Eggs White | E99: 65 | F99: 15 | G99: 55 | H99: =ROUND(E99-G99,2) -> 10 | I99: 4 | J99: =FALSE() -> FALSE | K99: =IF(J99,1,0) -> 0 | L99: Medio (3-5) | M99: =ROUND(G99*I99,2) -> 220 | N99: =ROUND(H99*I99,2) -> 40 | O99: 348 | P99: 6 | Q99: 51-100 | R99: 11-20% | S99: 5 | T99: 1
A100: P0099 | B100: Cooking Essentials | C100: Alimentos y bebidas | D100: Fortune Sunlite Refined Sunflower (Pouch) | E100: 230 | F100: 4 | G100: 219 | H100: =ROUND(E100-G100,2) -> 11 | I100: 6 | J100: =FALSE() -> FALSE | K100: =IF(J100,1,0) -> 0 | L100: Alto (6) | M100: =ROUND(G100*I100,2) -> 1314 | N100: =ROUND(H100*I100,2) -> 66 | O100: 1000 | P100: 1 | Q100: 201-500 | R100: 1-10% | S100: 2 | T100: 1
A101: P0100 | B101: Cooking Essentials | C101: Alimentos y bebidas | D101: Aashirvaad Superior MP Atta | E101: 250 | F101: 2 | G101: 245 | H101: =ROUND(E101-G101,2) -> 5 | I101: 6 | J101: =FALSE() -> FALSE | K101: =IF(J101,1,0) -> 0 | L101: Alto (6) | M101: =ROUND(G101*I101,2) -> 1470 | N101: =ROUND(H101*I101,2) -> 30 | O101: 5000 | P101: 5 | Q101: 201-500 | R101: 1-10% | S101: 2 | T101: 1
A102: P0101 | B102: Cooking Essentials | C102: Alimentos y bebidas | D102: Amul Pure Ghee (Pouch) | E102: 255 | F102: 2 | G102: 249 | H102: =ROUND(E102-G102,2) -> 6 | I102: 6 | J102: =FALSE() -> FALSE | K102: =IF(J102,1,0) -> 0 | L102: Alto (6) | M102: =ROUND(G102*I102,2) -> 1494 | N102: =ROUND(H102*I102,2) -> 36 | O102: 500 | P102: 500 | Q102: 201-500 | R102: 1-10% | S102: 2 | T102: 1
A103: P0102 | B103: Cooking Essentials | C103: Alimentos y bebidas | D103: Arden Eggs Brown | E103: 85 | F103: 7 | G103: 79 | H103: =ROUND(E103-G103,2) -> 6 | I103: 4 | J103: =FALSE() -> FALSE | K103: =IF(J103,1,0) -> 0 | L103: Medio (3-5) | M103: =ROUND(G103*I103,2) -> 316 | N103: =ROUND(H103*I103,2) -> 24 | O103: 348 | P103: 6 | Q103: 51-100 | R103: 1-10% | S103: 5 | T103: 1
A104: P0103 | B104: Cooking Essentials | C104: Alimentos y bebidas | D104: Tata Salt Lite | E104: 40 | F104: 10 | G104: 36 | H104: =ROUND(E104-G104,2) -> 4 | I104: 6 | J104: =FALSE() -> FALSE | K104: =IF(J104,1,0) -> 0 | L104: Alto (6) | M104: =ROUND(G104*I104,2) -> 216 | N104: =ROUND(H104*I104,2) -> 24 | O104: 1000 | P104: 1 | Q104: 0-50 | R104: 1-10% | S104: 2 | T104: 1
A105: P0104 | B105: Cooking Essentials | C105: Alimentos y bebidas | D105: Saffola Gold Oil (Pouch) | E105: 215 | F105: 0 | G105: 215 | H105: =ROUND(E105-G105,2) -> 0 | I105: 6 | J105: =FALSE() -> FALSE | K105: =IF(J105,1,0) -> 0 | L105: Alto (6) | M105: =ROUND(G105*I105,2) -> 1290 | N105: =ROUND(H105*I105,2) -> 0 | O105: 1000 | P105: 1 | Q105: 201-500 | R105: Sin descuento | S105: 2 | T105: 1
A106: P0105 | B106: Cooking Essentials | C106: Alimentos y bebidas | D106: Fortune Sunlite Refined Sunflower (Jar) | E106: 925 | F106: 0 | G106: 925 | H106: =ROUND(E106-G106,2) -> 0 | I106: 6 | J106: =FALSE() -> FALSE | K106: =IF(J106,1,0) -> 0 | L106: Alto (6) | M106: =ROUND(G106*I106,2) -> 5550 | N106: =ROUND(H106*I106,2) -> 0 | O106: 5000 | P106: 5 | Q106: 500+ | R106: Sin descuento | S106: 2 | T106: 1
... A544: P0543 | B544: Cooking Essentials | C544: Alimentos y bebidas | D544: Figaro Pure Olive Oil | E544: 325 | F544: 8 | G544: 299 | H544: =ROUND(E544-G544,2) -> 26 | I544: 1 | J544: =FALSE() -> FALSE | K544: =IF(J544,1,0) -> 0 | L544: Bajo (1-2) | M544: =ROUND(G544*I544,2) -> 299 | N544: =ROUND(H544*I544,2) -> 26 | O544: 200 | P544: 200 | Q544: 201-500 | R544: 1-10% | S544: 2 | T544: 1
A545: P0544 | B545: Cooking Essentials | C545: Alimentos y bebidas | D545: Madhur Sugar | E545: 60 | F545: 6 | G545: 56 | H545: =ROUND(E545-G545,2) -> 4 | I545: 0 | J545: =TRUE() -> TRUE | K545: =IF(J545,1,0) -> 1 | L545: Agotado | M545: =ROUND(G545*I545,2) -> 0 | N545: =ROUND(H545*I545,2) -> 0 | O545: 1000 | P545: 1 | Q545: 51-100 | R545: 1-10% | S545: 2 | T545: 1
A546: P0545 | B546: Cooking Essentials | C546: Alimentos y bebidas | D546: Amul Fresh Cream | E546: 63 | F546: 0 | G546: 63 | H546: =ROUND(E546-G546,2) -> 0 | I546: 0 | J546: =TRUE() -> TRUE | K546: =IF(J546,1,0) -> 1 | L546: Agotado | M546: =ROUND(G546*I546,2) -> 0 | N546: =ROUND(H546*I546,2) -> 0 | O546: 250 | P546: 250 | Q546: 51-100 | R546: Sin descuento | S546: 4 | T546: 1
A547: P0546 | B547: Cooking Essentials | C547: Alimentos y bebidas | D547: Madhur Pure And Hygienic Sugar | E547: 295 | F547: 9 | G547: 266 | H547: =ROUND(E547-G547,2) -> 29 | I547: 0 | J547: =TRUE() -> TRUE | K547: =IF(J547,1,0) -> 1 | L547: Agotado | M547: =ROUND(G547*I547,2) -> 0 | N547: =ROUND(H547*I547,2) -> 0 | O547: 5000 | P547: 5 | Q547: 201-500 | R547: 1-10% | S547: 2 | T547: 1
A548: P0547 | B548: Cooking Essentials | C548: Alimentos y bebidas | D548: Satyam Poha Jada | E548: 35 | F548: 8 | G548: 32 | H548: =ROUND(E548-G548,2) -> 3 | I548: 0 | J548: =TRUE() -> TRUE | K548: =IF(J548,1,0) -> 1 | L548: Agotado | M548: =ROUND(G548*I548,2) -> 0 | N548: =ROUND(H548*I548,2) -> 0 | O548: 500 | P548: 500 | Q548: 0-50 | R548: 1-10% | S548: 2 | T548: 1
A549: P0548 | B549: Cooking Essentials | C549: Alimentos y bebidas | D549: Aashirvaad Superior MP Whole Wheat Atta | E549: 53 | F549: 1 | G549: 52 | H549: =ROUND(E549-G549,2) -> 1 | I549: 0 | J549: =TRUE() -> TRUE | K549: =IF(J549,1,0) -> 1 | L549: Agotado | M549: =ROUND(G549*I549,2) -> 0 | N549: =ROUND(H549*I549,2) -> 0 | O549: 1000 | P549: 1 | Q549: 51-100 | R549: 1-10% | S549: 2 | T549: 1
A550: P0549 | B550: Cooking Essentials | C550: Alimentos y bebidas | D550: Fortune Soyabean Oil | E550: 210 | F550: 13 | G550: 181 | H550: =ROUND(E550-G550,2) -> 29 | I550: 0 | J550: =TRUE() -> TRUE | K550: =IF(J550,1,0) -> 1 | L550: Agotado | M550: =ROUND(G550*I550,2) -> 0 | N550: =ROUND(H550*I550,2) -> 0 | O550: 1000 | P550: 1 | Q550: 201-500 | R550: 11-20% | S550: 2 | T550: 1
A551: P0550 | B551: Cooking Essentials | C551: Alimentos y bebidas | D551: Maggi Masala Ae Magic | E551: 58 | F551: 6 | G551: 54 | H551: =ROUND(E551-G551,2) -> 4 | I551: 0 | J551: =TRUE() -> TRUE | K551: =IF(J551,1,0) -> 1 | L551: Agotado | M551: =ROUND(G551*I551,2) -> 0 | N551: =ROUND(H551*I551,2) -> 0 | O551: 72 | P551: 72 | Q551: 51-100 | R551: 1-10% | S551: 2 | T551: 1
...

Sheet productos_unicos
A1: id_producto | B1: categoria | C1: grupo | D1: producto | E1: precio_lista | F1: descuento_pct | G1: precio_venta | H1: ahorro_unitario | I1: cantidad_disponible | J1: agotado | K1: agotado_num | L1: nivel_stock | M1: valor_inventario | N1: ahorro_potencial | O1: peso_gramos | P1: cantidad_paquete | Q1: rango_precio | R1: rango_descuento | S1: n_categorias | T1: es_listado_principal
A2: P0001 | B2: Fruits & Vegetables | C2: Alimentos y bebidas | D2: Onion | E2: 25 | F2: 16 | G2: 21 | H2: =ROUND(E2-G2,2) -> 4 | I2: 3 | J2: =FALSE() -> FALSE | K2: =IF(J2,1,0) -> 0 | L2: Medio (3-5) | M2: =ROUND(G2*I2,2) -> 63 | N2: =ROUND(H2*I2,2) -> 12 | O2: 1000 | P2: 1 | Q2: 0-50 | R2: 11-20% | S2: 1 | T2: 1
A3: P0002 | B3: Fruits & Vegetables | C3: Alimentos y bebidas | D3: Tomato Hybrid | E3: 42 | F3: 16 | G3: 35 | H3: =ROUND(E3-G3,2) -> 7 | I3: 3 | J3: =FALSE() -> FALSE | K3: =IF(J3,1,0) -> 0 | L3: Medio (3-5) | M3: =ROUND(G3*I3,2) -> 105 | N3: =ROUND(H3*I3,2) -> 21 | O3: 1000 | P3: 1 | Q3: 0-50 | R3: 11-20% | S3: 1 | T3: 1
A4: P0003 | B4: Fruits & Vegetables | C4: Alimentos y bebidas | D4: Tender Coconut | E4: 51 | F4: 15 | G4: 43 | H4: =ROUND(E4-G4,2) -> 8 | I4: 3 | J4: =FALSE() -> FALSE | K4: =IF(J4,1,0) -> 0 | L4: Medio (3-5) | M4: =ROUND(G4*I4,2) -> 129 | N4: =ROUND(H4*I4,2) -> 24 | O4: 58 | P4: 1 | Q4: 51-100 | R4: 11-20% | S4: 1 | T4: 1
A5: P0004 | B5: Fruits & Vegetables | C5: Alimentos y bebidas | D5: Coriander Leaves | E5: 20 | F5: 15 | G5: 17 | H5: =ROUND(E5-G5,2) -> 3 | I5: 3 | J5: =FALSE() -> FALSE | K5: =IF(J5,1,0) -> 0 | L5: Medio (3-5) | M5: =ROUND(G5*I5,2) -> 51 | N5: =ROUND(H5*I5,2) -> 9 | O5: 100 | P5: 100 | Q5: 0-50 | R5: 11-20% | S5: 1 | T5: 1
A6: P0005 | B6: Fruits & Vegetables | C6: Alimentos y bebidas | D6: Ladies Finger | E6: 14 | F6: 14 | G6: 12 | H6: =ROUND(E6-G6,2) -> 2 | I6: 3 | J6: =FALSE() -> FALSE | K6: =IF(J6,1,0) -> 0 | L6: Medio (3-5) | M6: =ROUND(G6*I6,2) -> 36 | N6: =ROUND(H6*I6,2) -> 6 | O6: 250 | P6: 250 | Q6: 0-50 | R6: 11-20% | S6: 1 | T6: 1
A7: P0006 | B7: Fruits & Vegetables | C7: Alimentos y bebidas | D7: Potato | E7: 35 | F7: 17 | G7: 29 | H7: =ROUND(E7-G7,2) -> 6 | I7: 3 | J7: =FALSE() -> FALSE | K7: =IF(J7,1,0) -> 0 | L7: Medio (3-5) | M7: =ROUND(G7*I7,2) -> 87 | N7: =ROUND(H7*I7,2) -> 18 | O7: 1000 | P7: 1 | Q7: 0-50 | R7: 11-20% | S7: 1 | T7: 1
A8: P0007 | B8: Fruits & Vegetables | C8: Alimentos y bebidas | D8: Lemon | E8: 75 | F8: 16 | G8: 63 | H8: =ROUND(E8-G8,2) -> 12 | I8: 3 | J8: =FALSE() -> FALSE | K8: =IF(J8,1,0) -> 0 | L8: Medio (3-5) | M8: =ROUND(G8*I8,2) -> 189 | N8: =ROUND(H8*I8,2) -> 36 | O8: 200 | P8: 200 | Q8: 51-100 | R8: 11-20% | S8: 1 | T8: 1
A9: P0008 | B9: Fruits & Vegetables | C9: Alimentos y bebidas | D9: Watermelon | E9: 58 | F9: 15 | G9: 49 | H9: =ROUND(E9-G9,2) -> 9 | I9: 3 | J9: =FALSE() -> FALSE | K9: =IF(J9,1,0) -> 0 | L9: Medio (3-5) | M9: =ROUND(G9*I9,2) -> 147 | N9: =ROUND(H9*I9,2) -> 27 | O9: 58 | P9: 1 | Q9: 51-100 | R9: 11-20% | S9: 1 | T9: 1
A10: P0009 | B10: Fruits & Vegetables | C10: Alimentos y bebidas | D10: Capsicum Green | E10: 23 | F10: 17 | G10: 19 | H10: =ROUND(E10-G10,2) -> 4 | I10: 3 | J10: =FALSE() -> FALSE | K10: =IF(J10,1,0) -> 0 | L10: Medio (3-5) | M10: =ROUND(G10*I10,2) -> 57 | N10: =ROUND(H10*I10,2) -> 12 | O10: 250 | P10: 250 | Q10: 0-50 | R10: 11-20% | S10: 1 | T10: 1
A11: P0010 | B11: Fruits & Vegetables | C11: Alimentos y bebidas | D11: Chilli Green | E11: 19 | F11: 15 | G11: 16 | H11: =ROUND(E11-G11,2) -> 3 | I11: 3 | J11: =FALSE() -> FALSE | K11: =IF(J11,1,0) -> 0 | L11: Medio (3-5) | M11: =ROUND(G11*I11,2) -> 48 | N11: =ROUND(H11*I11,2) -> 9 | O11: 100 | P11: 100 | Q11: 0-50 | R11: 11-20% | S11: 1 | T11: 1
A12: P0011 | B12: Fruits & Vegetables | C12: Alimentos y bebidas | D12: Banana Robusta | E12: 29 | F12: 17 | G12: 24 | H12: =ROUND(E12-G12,2) -> 5 | I12: 3 | J12: =FALSE() -> FALSE | K12: =IF(J12,1,0) -> 0 | L12: Medio (3-5) | M12: =ROUND(G12*I12,2) -> 72 | N12: =ROUND(H12*I12,2) -> 15 | O12: 348 | P12: 6 | Q12: 0-50 | R12: 11-20% | S12: 1 | T12: 1
A13: P0012 | B13: Fruits & Vegetables | C13: Alimentos y bebidas | D13: Garlic Indian | E13: 11 | F13: 18 | G13: 9 | H13: =ROUND(E13-G13,2) -> 2 | I13: 3 | J13: =FALSE() -> FALSE | K13: =IF(J13,1,0) -> 0 | L13: Medio (3-5) | M13: =ROUND(G13*I13,2) -> 27 | N13: =ROUND(H13*I13,2) -> 6 | O13: 100 | P13: 100 | Q13: 0-50 | R13: 11-20% | S13: 1 | T13: 1
... A88: P0087 | B88: Fruits & Vegetables | C88: Alimentos y bebidas | D88: Garlic | E88: 17 | F88: 23 | G88: 13 | H88: =ROUND(E88-G88,2) -> 4 | I88: 3 | J88: =FALSE() -> FALSE | K88: =IF(J88,1,0) -> 0 | L88: Medio (3-5) | M88: =ROUND(G88*I88,2) -> 39 | N88: =ROUND(H88*I88,2) -> 12 | O88: 200 | P88: 200 | Q88: 0-50 | R88: 21% o mas | S88: 1 | T88: 1
A89: P0088 | B89: Fruits & Vegetables | C89: Alimentos y bebidas | D89: Carrot | E89: 13 | F89: 15 | G89: 11 | H89: =ROUND(E89-G89,2) -> 2 | I89: 0 | J89: =TRUE() -> TRUE | K89: =IF(J89,1,0) -> 1 | L89: Agotado | M89: =ROUND(G89*I89,2) -> 0 | N89: =ROUND(H89*I89,2) -> 0 | O89: 250 | P89: 200 | Q89: 0-50 | R89: 11-20% | S89: 1 | T89: 1
A90: P0089 | B90: Fruits & Vegetables | C90: Alimentos y bebidas | D90: Beetroot | E90: 11 | F90: 18 | G90: 9 | H90: =ROUND(E90-G90,2) -> 2 | I90: 0 | J90: =TRUE() -> TRUE | K90: =IF(J90,1,0) -> 1 | L90: Agotado | M90: =ROUND(G90*I90,2) -> 0 | N90: =ROUND(H90*I90,2) -> 0 | O90: 250 | P90: 250 | Q90: 0-50 | R90: 11-20% | S90: 1 | T90: 1
A91: P0090 | B91: Fruits & Vegetables | C91: Alimentos y bebidas | D91: Moong Sprouts | E91: 35 | F91: 17 | G91: 29 | H91: =ROUND(E91-G91,2) -> 6 | I91: 0 | J91: =TRUE() -> TRUE | K91: =IF(J91,1,0) -> 1 | L91: Agotado | M91: =ROUND(G91*I91,2) -> 0 | N91: =ROUND(H91*I91,2) -> 0 | O91: 200 | P91: 200 | Q91: 0-50 | R91: 11-20% | S91: 1 | T91: 1
A92: P0091 | B92: Fruits & Vegetables | C92: Alimentos y bebidas | D92: Safal Frozen Mixed Vegetables | E92: 60 | F92: 5 | G92: 57 | H92: =ROUND(E92-G92,2) -> 3 | I92: 0 | J92: =TRUE() -> TRUE | K92: =IF(J92,1,0) -> 1 | L92: Agotado | M92: =ROUND(G92*I92,2) -> 0 | N92: =ROUND(H92*I92,2) -> 0 | O92: 500 | P92: 500 | Q92: 51-100 | R92: 1-10% | S92: 4 | T92: 1
A93: P0092 | B93: Fruits & Vegetables | C93: Alimentos y bebidas | D93: Safal Frozen Corn | E93: 41 | F93: 4 | G93: 39 | H93: =ROUND(E93-G93,2) -> 2 | I93: 0 | J93: =TRUE() -> TRUE | K93: =IF(J93,1,0) -> 1 | L93: Agotado | M93: =ROUND(G93*I93,2) -> 0 | N93: =ROUND(H93*I93,2) -> 0 | O93: 200 | P93: 200 | Q93: 0-50 | R93: 1-10% | S93: 4 | T93: 1
A94: P0093 | B94: Fruits & Vegetables | C94: Alimentos y bebidas | D94: Safal Frozen - Sweet Corn | E94: 160 | F94: 5 | G94: 152 | H94: =ROUND(E94-G94,2) -> 8 | I94: 0 | J94: =TRUE() -> TRUE | K94: =IF(J94,1,0) -> 1 | L94: Agotado | M94: =ROUND(G94*I94,2) -> 0 | N94: =ROUND(H94*I94,2) -> 0 | O94: 1000 | P94: 1 | Q94: 101-200 | R94: 1-10% | S94: 4 | T94: 1
A95: P0094 | B95: Cooking Essentials | C95: Alimentos y bebidas | D95: Maggi 2 Minute Masala Noodles | E95: 12 | F95: 0 | G95: 12 | H95: =ROUND(E95-G95,2) -> 0 | I95: 6 | J95: =FALSE() -> FALSE | K95: =IF(J95,1,0) -> 0 | L95: Alto (6) | M95: =ROUND(G95*I95,2) -> 72 | N95: =ROUND(H95*I95,2) -> 0 | O95: 70 | P95: 70 | Q95: 0-50 | R95: Sin descuento | S95: 5 | T95: 1
A96: P0095 | B96: Cooking Essentials | C96: Alimentos y bebidas | D96: iD Idli & Dosa Batter | E96: 80 | F96: 15 | G96: 68 | H96: =ROUND(E96-G96,2) -> 12 | I96: 6 | J96: =FALSE() -> FALSE | K96: =IF(J96,1,0) -> 0 | L96: Alto (6) | M96: =ROUND(G96*I96,2) -> 408 | N96: =ROUND(H96*I96,2) -> 72 | O96: 1000 | P96: 1 | Q96: 51-100 | R96: 11-20% | S96: 7 | T96: 1
A97: P0096 | B97: Cooking Essentials | C97: Alimentos y bebidas | D97: Tata Salt | E97: 24 | F97: 0 | G97: 24 | H97: =ROUND(E97-G97,2) -> 0 | I97: 6 | J97: =FALSE() -> FALSE | K97: =IF(J97,1,0) -> 0 | L97: Alto (6) | M97: =ROUND(G97*I97,2) -> 144 | N97: =ROUND(H97*I97,2) -> 0 | O97: 1000 | P97: 1 | Q97: 0-50 | R97: Sin descuento | S97: 2 | T97: 1
A98: P0097 | B98: Cooking Essentials | C98: Alimentos y bebidas | D98: Arden Eggs White | E98: 97 | F98: 0 | G98: 97 | H98: =ROUND(E98-G98,2) -> 0 | I98: 4 | J98: =FALSE() -> FALSE | K98: =IF(J98,1,0) -> 0 | L98: Medio (3-5) | M98: =ROUND(G98*I98,2) -> 388 | N98: =ROUND(H98*I98,2) -> 0 | O98: 696 | P98: 12 | Q98: 51-100 | R98: Sin descuento | S98: 5 | T98: 1
A99: P0098 | B99: Cooking Essentials | C99: Alimentos y bebidas | D99: Arden Eggs White | E99: 65 | F99: 15 | G99: 55 | H99: =ROUND(E99-G99,2) -> 10 | I99: 4 | J99: =FALSE() -> FALSE | K99: =IF(J99,1,0) -> 0 | L99: Medio (3-5) | M99: =ROUND(G99*I99,2) -> 220 | N99: =ROUND(H99*I99,2) -> 40 | O99: 348 | P99: 6 | Q99: 51-100 | R99: 11-20% | S99: 5 | T99: 1
A100: P0099 | B100: Cooking Essentials | C100: Alimentos y bebidas | D100: Fortune Sunlite Refined Sunflower (Pouch) | E100: 230 | F100: 4 | G100: 219 | H100: =ROUND(E100-G100,2) -> 11 | I100: 6 | J100: =FALSE() -> FALSE | K100: =IF(J100,1,0) -> 0 | L100: Alto (6) | M100: =ROUND(G100*I100,2) -> 1314 | N100: =ROUND(H100*I100,2) -> 66 | O100: 1000 | P100: 1 | Q100: 201-500 | R100: 1-10% | S100: 2 | T100: 1
A101: P0100 | B101: Cooking Essentials | C101: Alimentos y bebidas | D101: Aashirvaad Superior MP Atta | E101: 250 | F101: 2 | G101: 245 | H101: =ROUND(E101-G101,2) -> 5 | I101: 6 | J101: =FALSE() -> FALSE | K101: =IF(J101,1,0) -> 0 | L101: Alto (6) | M101: =ROUND(G101*I101,2) -> 1470 | N101: =ROUND(H101*I101,2) -> 30 | O101: 5000 | P101: 5 | Q101: 201-500 | R101: 1-10% | S101: 2 | T101: 1
A102: P0101 | B102: Cooking Essentials | C102: Alimentos y bebidas | D102: Amul Pure Ghee (Pouch) | E102: 255 | F102: 2 | G102: 249 | H102: =ROUND(E102-G102,2) -> 6 | I102: 6 | J102: =FALSE() -> FALSE | K102: =IF(J102,1,0) -> 0 | L102: Alto (6) | M102: =ROUND(G102*I102,2) -> 1494 | N102: =ROUND(H102*I102,2) -> 36 | O102: 500 | P102: 500 | Q102: 201-500 | R102: 1-10% | S102: 2 | T102: 1
A103: P0102 | B103: Cooking Essentials | C103: Alimentos y bebidas | D103: Arden Eggs Brown | E103: 85 | F103: 7 | G103: 79 | H103: =ROUND(E103-G103,2) -> 6 | I103: 4 | J103: =FALSE() -> FALSE | K103: =IF(J103,1,0) -> 0 | L103: Medio (3-5) | M103: =ROUND(G103*I103,2) -> 316 | N103: =ROUND(H103*I103,2) -> 24 | O103: 348 | P103: 6 | Q103: 51-100 | R103: 1-10% | S103: 5 | T103: 1
A104: P0103 | B104: Cooking Essentials | C104: Alimentos y bebidas | D104: Tata Salt Lite | E104: 40 | F104: 10 | G104: 36 | H104: =ROUND(E104-G104,2) -> 4 | I104: 6 | J104: =FALSE() -> FALSE | K104: =IF(J104,1,0) -> 0 | L104: Alto (6) | M104: =ROUND(G104*I104,2) -> 216 | N104: =ROUND(H104*I104,2) -> 24 | O104: 1000 | P104: 1 | Q104: 0-50 | R104: 1-10% | S104: 2 | T104: 1
A105: P0104 | B105: Cooking Essentials | C105: Alimentos y bebidas | D105: Saffola Gold Oil (Pouch) | E105: 215 | F105: 0 | G105: 215 | H105: =ROUND(E105-G105,2) -> 0 | I105: 6 | J105: =FALSE() -> FALSE | K105: =IF(J105,1,0) -> 0 | L105: Alto (6) | M105: =ROUND(G105*I105,2) -> 1290 | N105: =ROUND(H105*I105,2) -> 0 | O105: 1000 | P105: 1 | Q105: 201-500 | R105: Sin descuento | S105: 2 | T105: 1
A106: P0105 | B106: Cooking Essentials | C106: Alimentos y bebidas | D106: Fortune Sunlite Refined Sunflower (Jar) | E106: 925 | F106: 0 | G106: 925 | H106: =ROUND(E106-G106,2) -> 0 | I106: 6 | J106: =FALSE() -> FALSE | K106: =IF(J106,1,0) -> 0 | L106: Alto (6) | M106: =ROUND(G106*I106,2) -> 5550 | N106: =ROUND(H106*I106,2) -> 0 | O106: 5000 | P106: 5 | Q106: 500+ | R106: Sin descuento | S106: 2 | T106: 1
... A544: P0543 | B544: Cooking Essentials | C544: Alimentos y bebidas | D544: Figaro Pure Olive Oil | E544: 325 | F544: 8 | G544: 299 | H544: =ROUND(E544-G544,2) -> 26 | I544: 1 | J544: =FALSE() -> FALSE | K544: =IF(J544,1,0) -> 0 | L544: Bajo (1-2) | M544: =ROUND(G544*I544,2) -> 299 | N544: =ROUND(H544*I544,2) -> 26 | O544: 200 | P544: 200 | Q544: 201-500 | R544: 1-10% | S544: 2 | T544: 1
A545: P0544 | B545: Cooking Essentials | C545: Alimentos y bebidas | D545: Madhur Sugar | E545: 60 | F545: 6 | G545: 56 | H545: =ROUND(E545-G545,2) -> 4 | I545: 0 | J545: =TRUE() -> TRUE | K545: =IF(J545,1,0) -> 1 | L545: Agotado | M545: =ROUND(G545*I545,2) -> 0 | N545: =ROUND(H545*I545,2) -> 0 | O545: 1000 | P545: 1 | Q545: 51-100 | R545: 1-10% | S545: 2 | T545: 1
A546: P0545 | B546: Cooking Essentials | C546: Alimentos y bebidas | D546: Amul Fresh Cream | E546: 63 | F546: 0 | G546: 63 | H546: =ROUND(E546-G546,2) -> 0 | I546: 0 | J546: =TRUE() -> TRUE | K546: =IF(J546,1,0) -> 1 | L546: Agotado | M546: =ROUND(G546*I546,2) -> 0 | N546: =ROUND(H546*I546,2) -> 0 | O546: 250 | P546: 250 | Q546: 51-100 | R546: Sin descuento | S546: 4 | T546: 1
A547: P0546 | B547: Cooking Essentials | C547: Alimentos y bebidas | D547: Madhur Pure And Hygienic Sugar | E547: 295 | F547: 9 | G547: 266 | H547: =ROUND(E547-G547,2) -> 29 | I547: 0 | J547: =TRUE() -> TRUE | K547: =IF(J547,1,0) -> 1 | L547: Agotado | M547: =ROUND(G547*I547,2) -> 0 | N547: =ROUND(H547*I547,2) -> 0 | O547: 5000 | P547: 5 | Q547: 201-500 | R547: 1-10% | S547: 2 | T547: 1
A548: P0547 | B548: Cooking Essentials | C548: Alimentos y bebidas | D548: Satyam Poha Jada | E548: 35 | F548: 8 | G548: 32 | H548: =ROUND(E548-G548,2) -> 3 | I548: 0 | J548: =TRUE() -> TRUE | K548: =IF(J548,1,0) -> 1 | L548: Agotado | M548: =ROUND(G548*I548,2) -> 0 | N548: =ROUND(H548*I548,2) -> 0 | O548: 500 | P548: 500 | Q548: 0-50 | R548: 1-10% | S548: 2 | T548: 1
A549: P0548 | B549: Cooking Essentials | C549: Alimentos y bebidas | D549: Aashirvaad Superior MP Whole Wheat Atta | E549: 53 | F549: 1 | G549: 52 | H549: =ROUND(E549-G549,2) -> 1 | I549: 0 | J549: =TRUE() -> TRUE | K549: =IF(J549,1,0) -> 1 | L549: Agotado | M549: =ROUND(G549*I549,2) -> 0 | N549: =ROUND(H549*I549,2) -> 0 | O549: 1000 | P549: 1 | Q549: 51-100 | R549: 1-10% | S549: 2 | T549: 1
A550: P0549 | B550: Cooking Essentials | C550: Alimentos y bebidas | D550: Fortune Soyabean Oil | E550: 210 | F550: 13 | G550: 181 | H550: =ROUND(E550-G550,2) -> 29 | I550: 0 | J550: =TRUE() -> TRUE | K550: =IF(J550,1,0) -> 1 | L550: Agotado | M550: =ROUND(G550*I550,2) -> 0 | N550: =ROUND(H550*I550,2) -> 0 | O550: 1000 | P550: 1 | Q550: 201-500 | R550: 11-20% | S550: 2 | T550: 1
A551: P0550 | B551: Cooking Essentials | C551: Alimentos y bebidas | D551: Maggi Masala Ae Magic | E551: 58 | F551: 6 | G551: 54 | H551: =ROUND(E551-G551,2) -> 4 | I551: 0 | J551: =TRUE() -> TRUE | K551: =IF(J551,1,0) -> 1 | L551: Agotado | M551: =ROUND(G551*I551,2) -> 0 | N551: =ROUND(H551*I551,2) -> 0 | O551: 72 | P551: 72 | Q551: 51-100 | R551: 1-10% | S551: 2 | T551: 1
...

Sheet estadisticas
A1: Estadística descriptiva y valores de referencia
A2: Calculada con fórmulas sobre la hoja 'productos_unicos' (1 fila por producto, sin contar dos veces los productos listados en varias categorías). Desviación estándar muestral (STDEV).
A4: Variable | B4: Unidad | C4: n | D4: Media | E4: Mediana | F4: Moda | G4: Desv. estándar | H4: Mínimo | I4: Máximo | J4: Coef. variación
A5: precio_lista | B5: rupias | C5: =COUNT(productos_unicos!$E$2:$E$1801) -> 1800 | D5: =AVERAGE(productos_unicos!$E$2:$E$1801) -> 153.15889 | E5: =MEDIAN(productos_unicos!$E$2:$E$1801) -> 105 | F5: =IFERROR(MODE(productos_unicos!$E$2:$E$1801),"sin moda") -> 60 | G5: =STDEV(productos_unicos!$E$2:$E$1801) -> 162.71136 | H5: =MIN(productos_unicos!$E$2:$E$1801) -> 10 | I5: =MAX(productos_unicos!$E$2:$E$1801) -> 2600 | J5: =IF(D5=0,0,G5/D5) -> 1.0623697
A6: precio_venta | B6: rupias | C6: =COUNT(productos_unicos!$G$2:$G$1801) -> 1800 | D6: =AVERAGE(productos_unicos!$G$2:$G$1801) -> 138.66311 | E6: =MEDIAN(productos_unicos!$G$2:$G$1801) -> 99 | F6: =IFERROR(MODE(productos_unicos!$G$2:$G$1801),"sin moda") -> 25 | G6: =STDEV(productos_unicos!$G$2:$G$1801) -> 139.65628 | H6: =MIN(productos_unicos!$G$2:$G$1801) -> 9 | I6: =MAX(productos_unicos!$G$2:$G$1801) -> 1399 | J6: =IF(D6=0,0,G6/D6) -> 1.0071624
A7: descuento_pct | B7: % | C7: =COUNT(productos_unicos!$F$2:$F$1801) -> 1800 | D7: =AVERAGE(productos_unicos!$F$2:$F$1801) -> 7.7233333 | E7: =MEDIAN(productos_unicos!$F$2:$F$1801) -> 6 | F7: =IFERROR(MODE(productos_unicos!$F$2:$F$1801),"sin moda") -> 0 | G7: =STDEV(productos_unicos!$F$2:$F$1801) -> 8.8442838 | H7: =MIN(productos_unicos!$F$2:$F$1801) -> 0 | I7: =MAX(productos_unicos!$F$2:$F$1801) -> 51 | J7: =IF(D7=0,0,G7/D7) -> 1.1451382
A8: ahorro_unitario | B8: rupias | C8: =COUNT(productos_unicos!$H$2:$H$1801) -> 1800 | D8: =AVERAGE(productos_unicos!$H$2:$H$1801) -> 14.495778 | E8: =MEDIAN(productos_unicos!$H$2:$H$1801) -> 6 | F8: =IFERROR(MODE(productos_unicos!$H$2:$H$1801),"sin moda") -> 0 | G8: =STDEV(productos_unicos!$H$2:$H$1801) -> 40.685775 | H8: =MIN(productos_unicos!$H$2:$H$1801) -> 0 | I8: =MAX(productos_unicos!$H$2:$H$1801) -> 1201 | J8: =IF(D8=0,0,G8/D8) -> 2.8067328
A9: cantidad_disponible | B9: unidades | C9: =COUNT(productos_unicos!$I$2:$I$1801) -> 1800 | D9: =AVERAGE(productos_unicos!$I$2:$I$1801) -> 3.9977778 | E9: =MEDIAN(productos_unicos!$I$2:$I$1801) -> 5 | F9: =IFERROR(MODE(productos_unicos!$I$2:$I$1801),"sin moda") -> 6 | G9: =STDEV(productos_unicos!$I$2:$I$1801) -> 2.196818 | H9: =MIN(productos_unicos!$I$2:$I$1801) -> 0 | I9: =MAX(productos_unicos!$I$2:$I$1801) -> 6 | J9: =IF(D9=0,0,G9/D9) -> 0.54950979
A10: valor_inventario | B10: rupias | C10: =COUNT(productos_unicos!$M$2:$M$1801) -> 1800 | D10: =AVERAGE(productos_unicos!$M$2:$M$1801) -> 588.02978 | E10: =MEDIAN(productos_unicos!$M$2:$M$1801) -> 378 | F10: =IFERROR(MODE(productos_unicos!$M$2:$M$1801),"sin moda") -> 0 | G10: =STDEV(productos_unicos!$M$2:$M$1801) -> 747.98575 | H10: =MIN(productos_unicos!$M$2:$M$1801) -> 0 | I10: =MAX(productos_unicos!$M$2:$M$1801) -> 8394 | J10: =IF(D10=0,0,G10/D10) -> 1.2720202
A11: peso_gramos | B11: gramos | C11: =COUNT(productos_unicos!$O$2:$O$1801) -> 1798 | D11: =AVERAGE(productos_unicos!$O$2:$O$1801) -> 389.26029 | E11: =MEDIAN(productos_unicos!$O$2:$O$1801) -> 200 | F11: =IFERROR(MODE(productos_unicos!$O$2:$O$1801),"sin moda") -> 200 | G11: =STDEV(productos_unicos!$O$2:$O$1801) -> 701.20109 | H11: =MIN(productos_unicos!$O$2:$O$1801) -> 1 | I11: =MAX(productos_unicos!$O$2:$O$1801) -> 10000 | J11: =IF(D11=0,0,G11/D11) -> 1.8013682
A12: cantidad_paquete | B12: según producto | C12: =COUNT(productos_unicos!$P$2:$P$1801) -> 1797 | D12: =AVERAGE(productos_unicos!$P$2:$P$1801) -> 201.55036 | E12: =MEDIAN(productos_unicos!$P$2:$P$1801) -> 150 | F12: =IFERROR(MODE(productos_unicos!$P$2:$P$1801),"sin moda") -> 200 | G12: =STDEV(productos_unicos!$P$2:$P$1801) -> 196.66168 | H12: =MIN(productos_unicos!$P$2:$P$1801) -> 1 | I12: =MAX(productos_unicos!$P$2:$P$1801) -> 1500 | J12: =IF(D12=0,0,G12/D12) -> 0.97574459
A14: Valores de referencia para validar las medidas de Power BI
A15: Indicador | B15: Valor | C15: Cómo se calcula
A16: Filas en datos_limpios (listados) | B16: =COUNTA(datos_limpios!A2:A3730) -> 3729 | C16: Un producto aparece una vez por categoría en la que está listado
A17: Productos únicos | B17: =COUNTA(productos_unicos!A2:A1801) -> 1800 | C17: Filas con es_listado_principal = 1
A18: Valor de inventario, solo únicos (₹) | B18: =SUM(productos_unicos!M2:M1801) -> 1058453.6 | C18: Cifra correcta para el total del inventario
A19: Valor de inventario, todos los listados (₹) | B19: =SUM(datos_limpios!M2:M3730) -> 2241460.6 | C19: Cuenta dos o más veces los productos repetidos; no usar como total
A20: % de productos agotados (únicos) | B20: =AVERAGE(productos_unicos!K2:K1801) -> 0.12055556 | C20: Productos con cantidad_disponible = 0
A21: Descuento promedio (únicos, %) | B21: =AVERAGE(productos_unicos!F2:F1801) -> 7.7233333 | C21: Promedio simple de descuento_pct
A22: Ahorro potencial total, únicos (₹) | B22: =SUM(productos_unicos!N2:N1801) -> 115512.4 | C22: Σ (precio_lista − precio_venta) × cantidad_disponible
A23: Total de datos en datos_limpios | B23: =COUNTA(datos_limpios!A2:A3730)*20 -> 74580 | C23: Filas × 20 columnas (valores vacíos incluidos)

Sheet diccionario
A1: Diccionario de datos
A3: Columna | B3: Tipo | C3: Unidad | D3: Descripción | E3: Origen
A4: id_producto | B4: texto | C4: — | D4: Identificador creado por nosotros (el dataset original no trae ID). Dos filas con el mismo nombre, precios, descuento, stock, peso y paquete comparten ID. | E4: Nueva
A5: categoria | B5: texto | C5: — | D5: Categoría de la tienda (14 categorías). Original: Category. | E5: Original (renombrada)
A6: grupo | B6: texto | C6: — | D6: Agrupación de las 14 categorías en 3 grupos. SUPUESTO nuestro: Paan Corner se ubica en Cuidado personal y salud porque su lista de productos es idéntica a la de Personal Care. | E6: Nueva
A7: producto | B7: texto | C7: — | D7: Nombre del producto, sin espacios sobrantes. Original: name. | E7: Original (renombrada)
A8: precio_lista | B8: número | C8: rupias (₹) | D8: Precio máximo de venta (MRP). Original: mrp ÷ 100. SUPUESTO: el original viene en paise (centésimas de rupia); confirmar en la descripción del dataset en Kaggle. | E8: Original (÷100)
A9: descuento_pct | B9: entero | C9: % (0–100) | D9: Porcentaje de descuento. Original: discountPercent. | E9: Original (renombrada)
A10: precio_venta | B10: número | C10: rupias (₹) | D10: Precio con descuento. Original: discountedSellingPrice ÷ 100. | E10: Original (÷100)
A11: ahorro_unitario | B11: número | C11: rupias (₹) | D11: Fórmula: precio_lista − precio_venta. | E11: Nueva
A12: cantidad_disponible | B12: entero | C12: unidades | D12: Unidades disponibles. Original: availableQuantity. El máximo observado es 6 y es el valor más frecuente, por lo que probablemente está topado; valor_inventario es un indicador relativo, no el valor real del stock. | E12: Original (renombrada)
A13: agotado | B13: lógico | C13: VERDADERO/FALSO | D13: Original: outOfStock. Coincide exactamente con cantidad_disponible = 0. | E13: Original (renombrada)
A14: agotado_num | B14: entero | C14: 0/1 | D14: Fórmula: 1 si agotado, 0 si no. Facilita medidas DAX y promedios. | E14: Nueva
... A23: es_listado_principal | B23: entero | C23: 0/1 | D23: 1 en la primera aparición de cada id_producto. Filtrar por 1 para totales sin duplicar productos. | E23: Nueva

Sheet limpieza
A1: Registro de limpieza
A3: Paso | B3: Qué se hizo | C3: Filas o valores afectados | D3: Filas restantes
A4: 0. Carga | B4: Filas y columnas originales | C4: 3732 | D4: 3732
A5: 1. Texto | B5: Nombres con espacios sobrantes corregidos (categoria y producto) | C5: 337 | D5: 3732
A6: 2. Duplicados | B6: Filas identicas en todas las columnas eliminadas | C6: 2 | D6: 3730
A7: 3. Precios | B7: Filas con precio de lista o de venta en 0 eliminadas | C7: 1 | D7: 3729
A8: 4. Ceros invalidos | B8: peso_gramos = 0 convertido a vacio | C8: 4 | D8: 3729
A9: 4. Ceros invalidos | B9: cantidad_paquete = 0 convertido a vacio | C9: 6 | D9: 3729
A10: 5. Unidades | B10: precio_lista y precio_venta divididos entre 100 (paise a rupias) | C10: 3729 | D10: 3729
A11: 6. Identificador | B11: Productos unicos detectados (id_producto) | C11: 1800 | D11: 3729
A12: 6. Identificador | B12: Productos listados en 2 o mas categorias | C12: 1281 | D12: 3729
A13: 7. Derivadas | B13: Columnas nuevas agregadas | C13: 11 | D13: 3729
A15: Hallazgos que afectan el análisis
A16: Listas repetidas entre categorías: Cooking Essentials = Munchies (514 filas), Chocolates & Candies = Ice Cream & Desserts = Packaged Food (388), Paan Corner = Personal Care (343) y Beverages = Dairy, Bread & Batter (129) contienen los mismos productos con los mismos valores.
A17: Por eso hay 3,729 filas pero solo 1,800 productos únicos. Sumar sobre todas las filas más que duplica el valor del inventario; para totales usar es_listado_principal = 1.
A18: No hay columna de fecha: no se pueden hacer tendencias en el tiempo con este dataset.
A19: cantidad_disponible parece topado en 6 unidades; el valor de inventario es un indicador relativo.
A20: Los ceros en descuento_pct (1,177 filas) son válidos: productos sin descuento.
A21: Los vacíos en peso_gramos y cantidad_paquete se conservaron como vacíos para no inventar datos; los promedios los ignoran.
